Workbook

Sheet SFigure7
A1: cc-pVTZ cart no frzn core
A2: EPT@HF vs EXP | F2: EPT@B3LYP vs EXP | K2: EPT@LDA vs EXP | P2: EPT@revPBE vs EXP
A3: SGN AVE | B3: 0.81505838 | C3: -0.40033347 | D3: 0.20197292 | E3: 0.093619103 | F3: SGN AVE | G3: 0.65645266 | H3: -0.52969631 | I3: 0.18587999 | J3: 0.048190847 | K3: SGN AVE | L3: 0.67636003 | M3: -0.37134439 | N3: 0.30550569 | O3: 0.18344779 | P3: SGN AVE | Q3: 0.56743985 | R3: -0.41384046 | S3: 0.20795256 | T3: 0.10132278
A4: MAE | B4: 0.97055894 | C4: 0.65086511 | D4: 0.40966705 | E4: 0.37898003 | F4: MAE | G4: 0.93382819 | H4: 0.71076902 | I4: 0.43231221 | J4: 0.39869203 | K4: MAE | L4: 0.95972676 | M4: 0.63962217 | N4: 0.50242383 | O4: 0.44565759 | P4: MAE | Q4: 0.87394813 | R4: 0.62797829 | S4: 0.4654048 | T4: 0.45006375
A5: RMSD | B5: 1.1436705 | C5: 0.85700097 | D5: 0.5126072 | E5: 0.47377765 | F5: RMSD | G5: 1.0835575 | H5: 0.91084471 | I5: 0.59007013 | J5: 0.50150492 | K5: RMSD | L5: 1.1354608 | M5: 0.81056308 | N5: 0.6905944 | O5: 0.61013778 | P5: RMSD | Q5: 1.0520357 | R5: 0.81899513 | S5: 0.63240792 | T5: 0.576111
B6: KT | C6: D2 | D6: P3 | E6: P3+ | G6: semi KT | H6: semi D2 | I6: semi P3 | J6: semi P3+ | L6: semi KT | M6: semi D2 | N6: semi P3 | O6: semi P3+ | Q6: semi KT | R6: semi D2 | S6: semi P3 | T6: semi P3+
B8: AVE PS | C8: 0.8997209 | D8: 0.91888319 | E8: 0.9137786 | G8: AVE PS | H8: 0.89309644 | I8: 0.9187364 | J8: 0.91280255 | L8: AVE PS | M8: 0.89381805 | N8: 0.91567277 | O8: 0.91083498 | Q8: AVE PS | R8: 0.89518202 | S8: 0.91477522 | T8: 0.91079607
A10: EPT@HF vs BD-T1 | F10: EPT@B3LYP vs BD-T1 | K10: EPT@LDA vs BD-T1 | P10: EPT@revPBE vs BD-T1
A11: SGN AVE | B11: 0.77948262 | C11: -0.43590923 | D11: 0.16639717 | E11: 0.058043346 | F11: SGN AVE | G11: 0.6208769 | H11: -0.56527206 | I11: 0.15030423 | J11: 0.01261509 | K11: SGN AVE | L11: 0.64078427 | M11: -0.40692015 | N11: 0.26992993 | O11: 0.14787204 | P11: SGN AVE | Q11: 0.53186409 | R11: -0.44941621 | S11: 0.1723768 | T11: 0.065747025
A12: MAE | B12: 0.91489329 | C12: 0.45382403 | D12: 0.27458613 | E12: 0.21016025 | F12: MAE | G12: 0.86157139 | H12: 0.57001612 | I12: 0.35417956 | J12: 0.26621929 | K12: MAE | L12: 0.87719703 | M12: 0.51447616 | N12: 0.44519013 | O12: 0.34793107 | P12: MAE | Q12: 0.79372603 | R12: 0.52329248 | S12: 0.40207783 | T12: 0.3350455
A13: RMSD | B13: 1.1428343 | C13: 0.65278257 | D13: 0.40097449 | E13: 0.2922056 | F13: RMSD | G13: 1.0718078 | H13: 0.71764687 | I13: 0.51952247 | J13: 0.35608227 | K13: RMSD | L13: 1.118803 | M13: 0.62354713 | N13: 0.64827198 | O13: 0.52679086 | P13: RMSD | Q13: 1.0237374 | R13: 0.64320448 | S13: 0.57764117 | T13: 0.48383253
B14: KT | C14: D2 | D14: P3 | E14: P3+ | G14: semi KT | H14: semi D2 | I14: semi P3 | J14: semi P3+ | L14: semi KT | M14: semi D2 | N14: semi P3 | O14: semi P3+ | Q14: semi KT | R14: semi D2 | S14: semi P3 | T14: semi P3+
F15: Diff | G15: =G12-B12 -> -0.053321903 | H15: =H12-C12 -> 0.11619209 | I15: =I12-D12 -> 0.079593425 | J15: =J12-E12 -> 0.056059036 | K15: Diff | L15: =B12-L12 -> 0.037696264 | M15: =C12-M12 -> -0.06065213 | N15: =D12-N12 -> -0.17060399 | O15: =E12-O12 -> -0.13777082 | P15: Diff | Q15: =B12-Q12 -> 0.12116726 | R15: =C12-R12 -> -0.069468456 | S15: =D12-S12 -> -0.1274917 | T15: =E12-T12 -> -0.12488525
B16: AVE PS | C16: 0.8997209 | D16: 0.91888319 | E16: 0.9137786 | G16: AVE PS | H16: 0.89309644 | I16: 0.9187364 | J16: 0.91280255 | L16: AVE PS | M16: 0.89381805 | N16: 0.91567277 | O16: 0.91083498 | Q16: AVE PS | R16: 0.89518202 | S16: 0.91477522 | T16: 0.91079607

Sheet STable7
B2: BeO
B3: orb | C3: kt | D3: d2 | E3: kt | F3: d2 | G3: ps | H3: l3 | I3: l3 | J3: ps | K3: exp | L3: sgn err kt | M3: sgn err d2 | N3: sgn err l3 | O3: BD-T1 | P3: sgn err kt | Q3: sgn err d2 | R3: sgn err l3 | S3: abs kt-BDT1 | T3: abs d2-BDT1 | U3: abs l3-BDT1
A4: HF | B4: σ | C4: -0.065776979 | D4: -0.084902729 | E4: =C4*27.2114 -> -1.7898837 | F4: =D4*27.2114 -> -2.3103221 | G4: 0.97199517 | H4: -0.079668239 | I4: =H4*27.2114 -> -2.1678843 | J4: 0.97433954 | K4: 2.337 | L4: =-E4-K4 -> -0.5471163 | M4: =-F4-K4 -> -0.026677885 | N4: =-I4-K4 -> -0.16911569 | O4: 2.036 | P4: =-E4-O4 -> -0.2461163 | Q4: =-F4-O4 -> 0.27432211 | R4: =-I4-O4 -> 0.13188431 | S4: =ABS(P4) -> 0.2461163 | T4: =ABS(Q4) -> 0.27432211 | U4: =ABS(R4) -> 0.13188431
A5: B3LYP | B5: σ | C5: -0.056240886 | D5: -0.072400042 | E5: =C5*27.2114 -> -1.5303933 | F5: =D5*27.2114 -> -1.9701065 | G5: 0.96442798 | H5: -0.06849908 | I5: =H5*27.2114 -> -1.8639559 | J5: 0.97069883 | K5: 2.337 | L5: =-E5-K5 -> -0.80660674 | M5: =-F5-K5 -> -0.3668935 | N5: =-I5-K5 -> -0.47304415 | O5: 2.036 | P5: =-E5-O5 -> -0.50560674 | Q5: =-F5-O5 -> -0.065893497 | R5: =-I5-O5 -> -0.17204415 | S5: =ABS(P5) -> 0.50560674 | T5: =ABS(Q5) -> 0.065893497 | U5: =ABS(R5) -> 0.17204415
A6: LDA | B6: σ | C6: -0.055268373 | D6: -0.070329409 | E6: =C6*27.2114 -> -1.5039298 | F6: =D6*27.2114 -> -1.9137617 | G6: 0.9626049 | H6: -0.067333248 | I6: =H6*27.2114 -> -1.8322319 | J6: 0.96995082 | K6: 2.337 | L6: =-E6-K6 -> -0.8330702 | M6: =-F6-K6 -> -0.42323831 | N6: =-I6-K6 -> -0.50476807 | O6: 2.036 | P6: =-E6-O6 -> -0.5320702 | Q6: =-F6-O6 -> -0.12223831 | R6: =-I6-O6 -> -0.20376807 | S6: =ABS(P6) -> 0.5320702 | T6: =ABS(Q6) -> 0.12223831 | U6: =ABS(R6) -> 0.20376807
A7: revPBE | B7: σ | C7: -0.054622519 | D7: -0.068535057 | E7: =C7*27.2114 -> -1.4863552 | F7: =D7*27.2114 -> -1.8649349 | G7: 0.96103782 | H7: -0.066371916 | I7: =H7*27.2114 -> -1.8060728 | J7: 0.9689406 | K7: 2.337 | L7: =-E7-K7 -> -0.85064478 | M7: =-F7-K7 -> -0.47206515 | N7: =-I7-K7 -> -0.53092724 | O7: 2.036 | P7: =-E7-O7 -> -0.54964478 | Q7: =-F7-O7 -> -0.17106515 | R7: =-I7-O7 -> -0.22992724 | S7: =ABS(P7) -> 0.54964478 | T7: =ABS(Q7) -> 0.17106515 | U7: =ABS(R7) -> 0.22992724
B9: BN
B10: orb | C10: kt | D10: d2 | E10: kt | F10: d2 | G10: ps | H10: l3 | I10: l3 | J10: ps | K10: exp | L10: sgn err kt | M10: sgn err d2 | N10: sgn err l3 | O10: BD-T1 | P10: sgn err kt | Q10: sgn err d2 | R10: sgn err l3 | S10: abs kt-BDT1 | T10: abs d2-BDT1 | U10: abs l3-BDT1
A11: HF | B11: σ | C11: -0.10874201 | D11: -0.13813492 | E11: =C11*27.2114 -> -2.9590223 | F11: =D11*27.2114 -> -3.7588447 | G11: 0.89355461 | H11: -0.12821572 | I11: =H11*27.2114 -> -3.4889292 | J11: 0.90473082 | K11: 3.16 | L11: =-E11-K11 -> -0.20097772 | M11: =-F11-K11 -> 0.59884466 | N11: =-I11-K11 -> 0.32892915 | O11: 2.657 | P11: =-E11-O11 -> 0.30202228 | Q11: =-F11-O11 -> 1.1018447 | R11: =-I11-O11 -> 0.83192915 | S11: =ABS(P11) -> 0.30202228 | T11: =ABS(Q11) -> 1.1018447 | U11: =ABS(R11) -> 0.83192915
A12: B3LYP | B12: σ | C12: -0.09577691 | D12: -0.11022286 | E12: =C12*27.2114 -> -2.6062238 | F12: =D12*27.2114 -> -2.9993183 | G12: 0.88381162 | H12: -0.10793031 | I12: =H12*27.2114 -> -2.9369348 | J12: 0.89958273 | K12: 3.16 | L12: =-E12-K12 -> -0.5537762 | M12: =-F12-K12 -> -0.16068166 | N12: =-I12-K12 -> -0.22306516 | O12: 2.657 | P12: =-E12-O12 -> -0.050776202 | Q12: =-F12-O12 -> 0.34231834 | R12: =-I12-O12 -> 0.27993484 | S12: =ABS(P12) -> 0.050776202 | T12: =ABS(Q12) -> 0.34231834 | U12: =ABS(R12) -> 0.27993484
A13: LDA | B13: σ | C13: x | D13: x | E13: x | F13: x | G13: x | H13: x | I13: x | J13: x | K13: 3.16 | L13: x | M13: x | N13: x | O13: 2.657 | P13: x | Q13: x | R13: x | S13: x | T13: x | U13: x
A14: revPBE | B14: σ | C14: x | D14: x | E14: x | F14: x | G14: x | H14: x | I14: x | J14: x | K14: 3.16 | L14: x | M14: x | N14: x | O14: 2.657 | P14: x | Q14: x | R14: x | S14: x | T14: x | U14: x
B16: C2
B17: orb | C17: kt | D17: d2 | E17: kt | F17: d2 | G17: ps | H17: l3 | I17: l3 | J17: ps | K17: exp | L17: sgn err kt | M17: sgn err d2 | N17: sgn err l3 | O17: BD-T1 | P17: sgn err kt | Q17: sgn err d2 | R17: sgn err l3 | S17: abs kt-BDT1 | T17: abs d2-BDT1 | U17: abs l3-BDT1
A18: HF | B18: σg | C18: -0.11581494 | D18: -0.14764118 | E18: =C18*27.2114 -> -3.1514867 | F18: =D18*27.2114 -> -4.0175231 | G18: 0.87253987 | H18: -0.13442714 | I18: =H18*27.2114 -> -3.6579507 | J18: 0.86943863 | K18: 3.273 | L18: =-E18-K18 -> -0.12151326 | M18: =-F18-K18 -> 0.74452314 | N18: =-I18-K18 -> 0.38495065 | O18: 2.516 | P18: =-E18-O18 -> 0.63548674 | Q18: =-F18-O18 -> 1.5015231 | R18: =-I18-O18 -> 1.1419507 | S18: =ABS(P18) -> 0.63548674 | T18: =ABS(Q18) -> 1.5015231 | U18: =ABS(R18) -> 1.1419507
A19: B3LYP | B19: σg | C19: -0.10483686 | D19: -0.11952287 | E19: =C19*27.2114 -> -2.8527576 | F19: =D19*27.2114 -> -3.2523847 | G19: 0.86546203 | H19: -0.11223887 | I19: =H19*27.2114 -> -3.0541767 | J19: 0.86646442 | K19: 3.273 | L19: =-E19-K19 -> -0.42024237 | M19: =-F19-K19 -> -0.020615277 | N19: =-I19-K19 -> -0.21882334 | O19: 2.516 | P19: =-E19-O19 -> 0.33675763 | Q19: =-F19-O19 -> 0.73638472 | R19: =-I19-O19 -> 0.53817666 | S19: =ABS(P19) -> 0.33675763 | T19: =ABS(Q19) -> 0.73638472 | U19: =ABS(R19) -> 0.53817666
A20: LDA | B20: σg | C20: x | D20: x | E20: x | F20: x | G20: x | H20: x | I20: x | J20: x | K20: 3.273 | L20: x | M20: x | N20: x | O20: 2.516 | P20: x | Q20: x | R20: x | S20: x | T20: x | U20: x
A21: revPBE | B21: σg | C21: x | D21: x | E21: x | F21: x | G21: x | H21: x | I21: x | J21: x | K21: 3.273 | L21: x | M21: x | N21: x | O21: 2.516 | P21: x | Q21: x | R21: x | S21: x | T21: x | U21: x
B23: Li2
B24: orb | C24: kt | D24: d2 | E24: kt | F24: d2 | G24: ps | H24: l3 | I24: l3 | J24: ps | K24: exp | L24: sgn err kt | M24: sgn err d2 | N24: sgn err l3 | O24: BD-T1 | P24: sgn err kt | Q24: sgn err d2 | R24: sgn err l3 | S24: abs kt-BDT1 | T24: abs d2-BDT1 | U24: abs l3-BDT1
A25: HF | B25: σu | C25: 0.0023941705 | D25: -0.0086865357 | E25: =C25*27.2114 -> 0.065148732 | F25: =D25*27.2114 -> -0.2363728 | G25: 0.96101833 | H25: -0.0094315062 | I25: =H25*27.2114 -> -0.25664449 | J25: 0.94387511 | K25: 0.54 | L25: =-E25-K25 -> -0.60514873 | M25: =-F25-K25 -> -0.3036272 | N25: =-I25-K25 -> -0.28335551 | O25: 0.279 | P25: =-E25-O25 -> -0.34414873 | Q25: =-F25-O25 -> -0.042627202 | R25: =-I25-O25 -> -0.022355513 | S25: =ABS(P25) -> 0.34414873 | T25: =ABS(Q25) -> 0.042627202 | U25: =ABS(R25) -> 0.022355513
A26: B3LYP | B26: σu | C26: 0.003416168 | D26: -0.0070949523 | E26: =C26*27.2114 -> 0.092958714 | F26: =D26*27.2114 -> -0.19306359 | G26: 0.96224915 | H26: -0.0078309488 | I26: =H26*27.2114 -> -0.21309108 | J26: 0.94529401 | K26: 0.54 | L26: =-E26-K26 -> -0.63295871 | M26: =-F26-K26 -> -0.34693641 | N26: =-I26-K26 -> -0.32690892 | O26: 0.279 | P26: =-E26-O26 -> -0.37195871 | Q26: =-F26-O26 -> -0.085936414 | R26: =-I26-O26 -> -0.06590892 | S26: =ABS(P26) -> 0.37195871 | T26: =ABS(Q26) -> 0.085936414 | U26: =ABS(R26) -> 0.06590892
A27: LDA | B27: σu | C27: 0.0030147247 | D27: -0.0078605829 | E27: =C27*27.2114 -> 0.082034879 | F27: =D27*27.2114 -> -0.21389747 | G27: 0.9611263 | H27: -0.0085653747 | I27: =H27*27.2114 -> -0.23307584 | J27: 0.9439539 | K27: 0.54 | L27: =-E27-K27 -> -0.62203488 | M27: =-F27-K27 -> -0.32610253 | N27: =-I27-K27 -> -0.30692416 | O27: 0.279 | P27: =-E27-O27 -> -0.36103488 | Q27: =-F27-O27 -> -0.065102535 | R27: =-I27-O27 -> -0.045924163 | S27: =ABS(P27) -> 0.36103488 | T27: =ABS(Q27) -> 0.065102535 | U27: =ABS(R27) -> 0.045924163
A28: revPBE | B28: σu | C28: 0.0032011625 | D28: -0.0075137694 | E28: =C28*27.2114 -> 0.087108112 | F28: =D28*27.2114 -> -0.20446018 | G28: 0.96153895 | H28: -0.0082154246 | I28: =H28*27.2114 -> -0.22355321 | J28: 0.94450245 | K28: 0.54 | L28: =-E28-K28 -> -0.62710811 | M28: =-F28-K28 -> -0.33553982 | N28: =-I28-K28 -> -0.31644679 | O28: 0.279 | P28: =-E28-O28 -> -0.36610811 | Q28: =-F28-O28 -> -0.074539817 | R28: =-I28-O28 -> -0.055446794 | S28: =ABS(P28) -> 0.36610811 | T28: =ABS(Q28) -> 0.074539817 | U28: =ABS(R28) -> 0.055446794
B30: NaH
B31: orb | C31: kt | D31: d2 | E31: kt | F31: d2 | G31: ps | H31: l3 | I31: l3 | J31: ps | K31: exp | L31: sgn err kt | M31: sgn err d2 | N31: sgn err l3 | O31: BD-T1 | P31: sgn err kt | Q31: sgn err d2 | R31: sgn err l3 | S31: abs kt-BDT1 | T31: abs d2-BDT1 | U31: abs l3-BDT1
A32: HF | B32: σ | C32: -0.0093593996 | D32: -0.012144451 | E32: =C32*27.2114 -> -0.25468237 | F32: =D32*27.2114 -> -0.33046751 | G32: 0.99289682 | H32: -0.012332699 | I32: =H32*27.2114 -> -0.33559 | J32: 0.99027737 | K32: 0.366 | L32: =-E32-K32 -> -0.11131763 | M32: =-F32-K32 -> -0.035532487 | N32: =-I32-K32 -> -0.030410004 | O32: 0.316 | P32: =-E32-O32 -> -0.061317633 | Q32: =-F32-O32 -> 0.014467513 | R32: =-I32-O32 -> 0.019589996 | S32: =ABS(P32) -> 0.061317633 | T32: =ABS(Q32) -> 0.014467513 | U32: =ABS(R32) -> 0.019589996
A33: B3LYP | B33: σ | C33: -0.0064405599 | D33: -0.0095535424 | E33: =C33*27.2114 -> -0.17525665 | F33: =D33*27.2114 -> -0.25996526 | G33: 0.9899993 | H33: -0.0094573279 | I33: =H33*27.2114 -> -0.25734713 | J33: 0.98668601 | K33: 0.366 | L33: =-E33-K33 -> -0.19074335 | M33: =-F33-K33 -> -0.10603474 | N33: =-I33-K33 -> -0.10865287 | O33: 0.316 | P33: =-E33-O33 -> -0.14074335 | Q33: =-F33-O33 -> -0.056034737 | R33: =-I33-O33 -> -0.058652868 | S33: =ABS(P33) -> 0.14074335 | T33: =ABS(Q33) -> 0.056034737 | U33: =ABS(R33) -> 0.058652868
A34: LDA | B34: σ | C34: -0.0061039379 | D34: -0.0094852485 | E34: =C34*27.2114 -> -0.1660967 | F34: =D34*27.2114 -> -0.25810689 | G34: 0.98894798 | H34: -0.0093514521 | I34: =H34*27.2114 -> -0.2544661 | J34: -0.0093514521 | K34: 0.366 | L34: =-E34-K34 -> -0.1999033 | M34: =-F34-K34 -> -0.10789311 | N34: =-I34-K34 -> -0.1115339 | O34: 0.316 | P34: =-E34-O34 -> -0.1499033 | Q34: =-F34-O34 -> -0.057893109 | R34: =-I34-O34 -> -0.061533897 | S34: =ABS(P34) -> 0.1499033 | T34: =ABS(Q34) -> 0.057893109 | U34: =ABS(R34) -> 0.061533897
A35: revPBE | B35: σ | C35: -0.0063925682 | D35: -0.0095905516 | E35: =C35*27.2114 -> -0.17395073 | F35: =D35*27.2114 -> -0.26097234 | G35: 0.98896421 | H35: -0.0094393572 | I35: =H35*27.2114 -> -0.25685812 | J35: 0.98531982 | K35: 0.366 | L35: =-E35-K35 -> -0.19204927 | M35: =-F35-K35 -> -0.10502766 | N35: =-I35-K35 -> -0.10914188 | O35: 0.316 | P35: =-E35-O35 -> -0.14204927 | Q35: =-F35-O35 -> -0.055027665 | R35: =-I35-O35 -> -0.059141876 | S35: =ABS(P35) -> 0.14204927 | T35: =ABS(Q35) -> 0.055027665 | U35: =ABS(R35) -> 0.059141876
B37: LiH
B38: orb | C38: kt | D38: d2 | E38: kt | F38: d2 | G38: ps | H38: l3 | I38: l3 | J38: ps | K38: exp | L38: sgn err kt | M38: sgn err d2 | N38: sgn err l3 | O38: BD-T1 | P38: sgn err kt | Q38: sgn err d2 | R38: sgn err l3 | S38: abs kt-BDT1 | T38: abs d2-BDT1 | U38: abs l3-BDT1
A39: HF | B39: σ | C39: -0.0073961359 | D39: -0.01018467 | E39: =C39*27.2114 -> -0.20125921 | F39: =D39*27.2114 -> -0.27713914 | G39: 0.99496342 | H39: -0.010592039 | I39: =H39*27.2114 -> -0.28822421 | J39: 0.99246183 | K39: 0.34 | L39: =-E39-K39 -> -0.13874079 | M39: =-F39-K39 -> -0.062860861 | N39: =-I39-K39 -> -0.051775794 | O39: 0.284 | P39: =-E39-O39 -> -0.082740788 | Q39: =-F39-O39 -> -0.0068608607 | R39: =-I39-O39 -> 0.004224206 | S39: =ABS(P39) -> 0.082740788 | T39: =ABS(Q39) -> 0.0068608607 | U39: =ABS(R39) -> 0.004224206
A40: B3LYP | B40: σ | C40: -0.0062329858 | D40: -0.0091701846 | E40: =C40*27.2114 -> -0.16960827 | F40: =D40*27.2114 -> -0.24953356 | G40: 0.99418216 | H40: -0.0095153852 | I40: =H40*27.2114 -> -0.25892695 | J40: 0.99148972 | K40: 0.34 | L40: =-E40-K40 -> -0.17039173 | M40: =-F40-K40 -> -0.090466439 | N40: =-I40-K40 -> -0.081073047 | O40: 0.284 | P40: =-E40-O40 -> -0.11439173 | Q40: =-F40-O40 -> -0.034466439 | R40: =-I40-O40 -> -0.025073047 | S40: =ABS(P40) -> 0.11439173 | T40: =ABS(Q40) -> 0.034466439 | U40: =ABS(R40) -> 0.025073047
A41: LDA | B41: σ | C41: -0.0061901803 | D41: -0.0093121524 | E41: =C41*27.2114 -> -0.16844347 | F41: =D41*27.2114 -> -0.2533967 | G41: 0.99381516 | H41: -0.0096627005 | I41: =H41*27.2114 -> -0.26293561 | J41: 0.99096269 | K41: 0.34 | L41: =-E41-K41 -> -0.17155653 | M41: =-F41-K41 -> -0.086603297 | N41: =-I41-K41 -> -0.077064392 | O41: 0.284 | P41: =-E41-O41 -> -0.11555653 | Q41: =-F41-O41 -> -0.030603297 | R41: =-I41-O41 -> -0.021064392 | S41: =ABS(P41) -> 0.11555653 | T41: =ABS(Q41) -> 0.030603297 | U41: =ABS(R41) -> 0.021064392
A42: revPBE | B42: σ | C42: -0.0060814703 | D42: -0.0090969799 | E42: =C42*27.2114 -> -0.16548532 | F42: =D42*27.2114 -> -0.24754156 | G42: 0.9937991 | H42: -0.0094239188 | I42: =H42*27.2114 -> -0.25643802 | J42: 0.99099132 | K42: 0.34 | L42: =-E42-K42 -> -0.17451468 | M42: =-F42-K42 -> -0.09245844 | N42: =-I42-K42 -> -0.083561977 | O42: 0.284 | P42: =-E42-O42 -> -0.11851468 | Q42: =-F42-O42 -> -0.03645844 | R42: =-I42-O42 -> -0.027561977 | S42: =ABS(P42) -> 0.11851468 | T42: =ABS(Q42) -> 0.03645844 | U42: =ABS(R42) -> 0.027561977
A44: NaLi
B45: orb | C45: kt | D45: d2 | E45: kt | F45: d2 | G45: ps | H45: l3 | I45: l3 | J45: ps | K45: exp | L45: sgn err kt | M45: sgn err d2 | N45: sgn err l3 | O45: BD-T1 | P45: sgn err kt | Q45: sgn err d2 | R45: sgn err l3 | S45: abs kt-BDT1 | T45: abs d2-BDT1 | U45: abs l3-BDT1
A46: HF | B46: σ | C46: 0.0014062257 | D46: -0.0096662664 | E46: =C46*27.2114 -> 0.038265369 | F46: =D46*27.2114 -> -0.26303264 | G46: 0.9592851 | H46: -0.0101245 | I46: =H46*27.2114 -> -0.27550181 | J46: 0.94289903 | K46: 0.452 | L46: =-E46-K46 -> -0.49026537 | M46: =-F46-K46 -> -0.18896736 | N46: =-I46-K46 -> -0.17649819 | O46: 0.275 | P46: =-E46-O46 -> -0.31326537 | Q46: =-F46-O46 -> -0.011967358 | R46: =-I46-O46 -> 0.00050180806 | S46: =ABS(P46) -> 0.31326537 | T46: =ABS(Q46) -> 0.011967358 | U46: =ABS(R46) -> 0.00050180806
A47: B3LYP | B47: σ | C47: 0.0028834218 | D47: -0.007881657 | E47: =C47*27.2114 -> 0.078461943 | F47: =D47*27.2114 -> -0.21447092 | G47: 0.95933884 | H47: -0.0082899897 | I47: =H47*27.2114 -> -0.22558223 | J47: 0.9425618 | K47: 0.452 | L47: =-E47-K47 -> -0.53046194 | M47: =-F47-K47 -> -0.23752908 | N47: =-I47-K47 -> -0.22641777 | O47: 0.275 | P47: =-E47-O47 -> -0.35346194 | Q47: =-F47-O47 -> -0.060529077 | R47: =-I47-O47 -> -0.049417775 | S47: =ABS(P47) -> 0.35346194 | T47: =ABS(Q47) -> 0.060529077 | U47: =ABS(R47) -> 0.049417775
...

Sheet SFigure25-27
A1: BN | B1: ha | C1: ha | D1: ev | E1: ev (theory) | G1: ev (exp)
A2: CCSD(T)/cc-PVTZ | B2: singlet | C2: triplet gs | D2: gap | E2: RMR CCSD(T) A | F2: sgn err | G2: exp | H2: sgn err
A3: hf | B3: -79.267834 | C3: -79.266908 | D3: =(B3-C3)*27.2114 -> -0.025205376 | E3: 0.05232 | F3: =D3-E3 -> -0.077525376 | G3: 0.01897 | H3: =D3-G3 -> -0.044175376
A4: b3lyp | B4: -79.26465 | C4: -79.265499 | D4: =(B4-C4)*27.2114 -> 0.023098941 | E4: 0.05232 | F4: =D4-E4 -> -0.029221059 | G4: 0.01897 | H4: =D4-G4 -> 0.0041289411
A5: lda | B5: -79.258533 | C5: -79.25932 | D5: =(B5-C5)*27.2114 -> 0.021420814 | E5: 0.05232 | F5: =D5-E5 -> -0.030899186 | G5: 0.01897 | H5: =D5-G5 -> 0.0024508141
A6: revPBE | B6: -79.264372 | C6: -79.265345 | D6: =(B6-C6)*27.2114 -> 0.026462814 | E6: 0.05232 | F6: =D6-E6 -> -0.025857186 | G6: 0.01897 | H6: =D6-G6 -> 0.0074928144
A7: SCAN | B7: -79.265021 | C7: -79.265947 | D7: =(B7-C7)*27.2114 -> 0.02518143 | E7: 0.05232 | F7: =D7-E7 -> -0.02713857 | G7: 0.01897 | H7: =D7-G7 -> 0.0062114296
A8: SCAN0 | B8: -79.265593 | C8: -79.266412 | D8: =(B8-C8)*27.2114 -> 0.022295933 | E8: 0.05232 | F8: =D8-E8 -> -0.030024067 | G8: 0.01897 | H8: =D8-G8 -> 0.0033259327
A10: C2 | B10: ha | C10: ha | D10: ev | E10: ev (theory) | G10: ev (exp)
A11: CCSD(T)/cc-PVTZ | B11: singlet gs | C11: triplet | D11: gap | E11: RMR CCSD(T) A | F11: sgn err | G11: exp | H11: sgn err
A12: hf | B12: -75.782463 | C12: -75.779631 | D12: =(C12-B12)*27.2114 -> 0.077076835 | E12: 0.1215 | F12: =D12-E12 -> -0.044423165 | G12: 0.08877 | H12: =D12-G12 -> -0.011693165
A13: b3lyp | B13: -75.781093 | C13: -75.777853 | D13: =(C13-B13)*27.2114 -> 0.088163303 | E13: 0.1215 | F13: =D13-E13 -> -0.033336697 | G13: 0.08877 | H13: =D13-G13 -> -0.00060669668
A14: lda | B14: -75.700487 | C14: -75.771562 | D14: =(C14-B14)*27.2114 -> -1.9340342 | E14: 0.1215 | F14: =D14-E14 -> -2.0555342 | G14: 0.08877 | H14: =D14-G14 -> -2.0228042
A15: revPBE | B15: -75.706472 | C15: -75.778401 | D15: =(C15-B15)*27.2114 -> -1.957304 | E15: 0.1215 | F15: =D15-E15 -> -2.078804 | G15: 0.08877 | H15: =D15-G15 -> -2.046074
A16: SCAN | B16: -75.781583 | C16: -75.778346 | D16: =(C16-B16)*27.2114 -> 0.088084662 | E16: 0.1215 | F16: =D16-E16 -> -0.033415338 | G16: 0.08877 | H16: =D16-G16 -> -0.00068533763
A17: SCAN0 | B17: -75.782002 | C17: -75.778865 | D17: =(C17-B17)*27.2114 -> 0.085351005 | E17: 0.1215 | F17: =D17-E17 -> -0.036148995 | G17: 0.08877 | H17: =D17-G17 -> -0.0034189949
A19: CH2 | B19: ha | C19: ha | D19: ev | E19: ev (theory) | G19: ev (exp)
A20: CCSD(T)/cc-PVTZ | B20: singlet | C20: triplet gs | D20: gap | E20: MRBWCCSDT/tz | F20: sgn err | G20: exp | H20: sgn err
A21: hf | B21: -39.060298 | C21: -39.077097 | D21: =(B21-C21)*27.2114 -> 0.45711179 | E21: =(10.18/627.5)*27.2114 -> 0.44145347 | F21: =D21-E21 -> 0.015658322 | G21: =(8.99/627.5)*27.2114 -> 0.38984938 | H21: =D21-G21 -> 0.067262411
A22: b3lyp | B22: -39.05945 | C22: -39.076262 | D22: =(B22-C22)*27.2114 -> 0.45747778 | E22: =(10.18/627.5)*27.2114 -> 0.44145347 | F22: =D22-E22 -> 0.016024315 | G22: =(8.99/627.5)*27.2114 -> 0.38984938 | H22: =D22-G22 -> 0.067628405
A23: lda | B23: -39.056284 | C23: -39.073187 | D23: =(B23-C23)*27.2114 -> 0.45993035 | E23: =(10.18/627.5)*27.2114 -> 0.44145347 | F23: =D23-E23 -> 0.018476879 | G23: =(8.99/627.5)*27.2114 -> 0.38984938 | H23: =D23-G23 -> 0.070080968
A24: revPBE | B24: -39.059355 | C24: -39.076172 | D24: =(B24-C24)*27.2114 -> 0.45760976 | E24: =(10.18/627.5)*27.2114 -> 0.44145347 | F24: =D24-E24 -> 0.016156291 | G24: =(8.99/627.5)*27.2114 -> 0.38984938 | H24: =D24-G24 -> 0.06776038
A25: SCAN | B25: -39.059678 | C25: -39.076498 | D25: =(B25-C25)*27.2114 -> 0.45770146 | E25: =(10.18/627.5)*27.2114 -> 0.44145347 | F25: =D25-E25 -> 0.016247993 | G25: =(8.99/627.5)*27.2114 -> 0.38984938 | H25: =D25-G25 -> 0.067852082
A26: SCAN0 | B26: -39.059942 | C26: -39.076753 | D26: =(B26-C26)*27.2114 -> 0.45744513 | E26: =(10.18/627.5)*27.2114 -> 0.44145347 | F26: =D26-E26 -> 0.015991662 | G26: =(8.99/627.5)*27.2114 -> 0.38984938 | H26: =D26-G26 -> 0.067595751
A28: NF | B28: ha | C28: ha | D28: ev | E28: ev (theory) | G28: ev (exp)
A29: CCSD(T)/cc-PVTZ | B29: singlet | C29: triplet gs | D29: gap | E29: MRBWCCSDT-α/tz | F29: sgn err | G29: exp | H29: sgn err
A30: hf | B30: -154.18237 | C30: -154.24907 | D30: =(B30-C30)*27.2114 -> 1.8149294 | E30: 1.53121 | F30: =D30-E30 -> 0.28371936 | G30: 1.41776 | H30: =D30-G30 -> 0.39716936
A31: b3lyp | B31: -154.18138 | C31: -154.24801 | D31: =(B31-C31)*27.2114 -> 1.8132782 | E31: 1.53121 | F31: =D31-E31 -> 0.28206817 | G31: 1.41776 | H31: =D31-G31 -> 0.39551817
A32: lda | B32: -154.17544 | C32: -154.24197 | D32: =(B32-C32)*27.2114 -> 1.8104833 | E32: 1.53121 | F32: =D32-E32 -> 0.27927329 | G32: 1.41776 | H32: =D32-G32 -> 0.39272329
A33: revPBE | B33: -154.18165 | C33: -154.24815 | D33: =(B33-C33)*27.2114 -> 1.8096288 | E33: 1.53121 | F33: =D33-E33 -> 0.27841885 | G33: 1.41776 | H33: =D33-G33 -> 0.39186885
A34: SCAN | B34: -154.18178 | C34: -154.2483 | D34: =(B34-C34)*27.2114 -> 1.8102302 | E34: 1.53121 | F34: =D34-E34 -> 0.27902022 | G34: 1.41776 | H34: =D34-G34 -> 0.39247022
A35: SCAN0 | B35: -154.18206 | C35: -154.24866 | D35: =(B35-C35)*27.2114 -> 1.8121051 | E35: 1.53121 | F35: =D35-E35 -> 0.28089509 | G35: 1.41776 | H35: =D35-G35 -> 0.39434509
A37: BO+ | B37: ha | C37: ha | D37: ev | E37: ev (theory) | G37: ev (exp)
A38: CCSD(T)/cc-PVTZ | B38: singlet gs | C38: triplet | D38: gap | E38: CMRCI/tz | F38: sgn err | G38: none | H38: sgn err
A39: hf | B39: -99.394874 | C39: -99.375657 | D39: =(C39-B39)*27.2114 -> 0.52293562 | E39: 0.5444769 | F39: =D39-E39 -> -0.021541276 | H39: =D39-G39 -> 0.52293562
A40: b3lyp | B40: -99.393883 | C40: -99.374143 | D40: =(C40-B40)*27.2114 -> 0.53713916 | E40: 0.5444769 | F40: =D40-E40 -> -0.0073377418 | H40: =D40-G40 -> 0.53713916
A41: lda | B41: -99.388126 | C41: -99.368075 | D41: =(C41-B41)*27.2114 -> 0.54561333 | E41: 0.5444769 | F41: =D41-E41 -> 0.0011364324 | H41: =D41-G41 -> 0.54561333
A42: revPBE | B42: -99.394016 | C42: -99.374024 | D42: =(C42-B42)*27.2114 -> 0.54401847 | E42: 0.5444769 | F42: =D42-E42 -> -0.00045842778 | H42: =D42-G42 -> 0.54401847
A43: SCAN | B43: -99.394377 | C43: -99.374557 | D43: =(C43-B43)*27.2114 -> 0.53934573 | E43: 0.5444769 | F43: =D43-E43 -> -0.0051311694 | H43: =D43-G43 -> 0.53934573
A44: SCAN0 | B44: -99.394503 | C44: -99.374996 | D44: =(C44-B44)*27.2114 -> 0.53081904 | E44: 0.5444769 | F44: =D44-E44 -> -0.013657862 | H44: =D44-G44 -> 0.53081904
...

Sheet SFigure28-32
B2: RCCSD(T)/cc-pVTZ | ST or TS Gap (eV) | J2: RCCSD(T)/cc-pVTZ | Signed Errors (eV) versus Theoretical reference data
B3: HF | C3: B3LYP | D3: LDA | E3: revPBE | F3: SCAN | G3: SCAN0 | J3: HF | K3: B3LYP | L3: LDA | M3: revPBE | N3: SCAN | O3: SCAN0
A4: BN | B4: -0.025205376 | C4: 0.023098941 | D4: 0.021420814 | E4: 0.026462814 | F4: 0.02518143 | G4: 0.022295933 | I4: BN | J4: -0.077525376 | K4: -0.029221059 | L4: -0.030899186 | M4: -0.025857186 | N4: -0.02713857 | O4: -0.030024067
A5: C2 | B5: 0.077076835 | C5: 0.088163303 | D5: -1.9340342 | E5: -1.957304 | F5: 0.088084662 | G5: 0.085351005 | I5: C2 | J5: -0.044423165 | K5: -0.033336697 | L5: -2.0555342 | M5: -2.078804 | N5: -0.033415338 | O5: -0.036148995
A6: CH2 | B6: 0.45711179 | C6: 0.45747778 | D6: 0.45993035 | E6: 0.45760976 | F6: 0.45770146 | G6: 0.45744513 | I6: CH2 | J6: 0.015658322 | K6: 0.016024315 | L6: 0.018476879 | M6: 0.016156291 | N6: 0.016247993 | O6: 0.015991662
A7: NF | B7: 1.8149294 | C7: 1.8132782 | D7: 1.8104833 | E7: 1.8096288 | F7: 1.8102302 | G7: 1.8121051 | I7: NF | J7: 0.28371936 | K7: 0.28206817 | L7: 0.27927329 | M7: 0.27841885 | N7: 0.27902022 | O7: 0.28089509
A8: BO+ | B8: 0.52293562 | C8: 0.53713916 | D8: 0.54561333 | E8: 0.54401847 | F8: 0.53934573 | G8: 0.53081904 | I8: BO+ | J8: -0.021541276 | K8: -0.0073377418 | L8: 0.0011364324 | M8: -0.00045842778 | N8: -0.0051311694 | O8: -0.013657862
A9: CN+ | B9: 0.22493324 | C9: 0.14158717 | D9: 0.14350041 | E9: 0.13955421 | F9: 0.14379701 | G9: 0.14820635 | I9: CN+ | J9: 0.12590704 | K9: 0.042560973 | L9: 0.044474206 | M9: 0.040528009 | N9: 0.044770811 | O9: 0.049180146
A10: O2 | B10: 1.2988031 | C10: 1.2995071 | D10: 1.297937 | E10: 1.2985302 | F10: 1.3011779 | G10: 1.3003212 | I10: O2 | J10: 0.20980312 | K10: 0.21050707 | L10: 0.20893698 | M10: 0.20953018 | N10: 0.21217785 | O10: 0.21132124
A11: NH | B11: 1.9356565 | C11: 1.9351325 | D11: 1.9308867 | E11: 1.9311944 | F11: 1.933136 | G11: 1.9361387 | I11: NH | J11: 0.15770053 | K11: 0.15717644 | L11: 0.15293064 | M11: 0.1532384 | N11: 0.15517994 | O11: 0.15818271
B13: RCCSD(T)/cc-pVTZ | T1 Diagnostic S=0 | J13: UCCSD(T)/cc-pVTZ | T1 Diagnostic S=1
B14: HF | C14: B3LYP | D14: LDA | E14: revPBE | F14: SCAN | G14: SCAN0 | J14: HF | K14: B3LYP | L14: LDA | M14: revPBE | N14: SCAN | O14: SCAN0
A15: BN | B15: 0.108 | C15: 0.04 | D15: 0.035 | E15: 0.027 | F15: 0.033 | G15: 0.046 | I15: BN | J15: 0.064 | K15: 0.015 | L15: 0.028 | M15: 0.019 | N15: 0.012 | O15: 0.015
A16: C2 | B16: 0.055 | C16: 0.023 | D16: 0.051 | E16: 0.05 | F16: 0.02 | G16: 0.027 | I16: C2 | J16: 0.032 | K16: 0.012 | L16: 0.019 | M16: 0.012 | N16: 0.01 | O16: 0.009
A17: CH2 | B17: 0.011 | C17: 0.012 | D17: 0.02 | E17: 0.014 | F17: 0.011 | G17: 0.007 | I17: CH2 | J17: 0.013 | K17: 0.013 | L17: 0.021 | M17: 0.011 | N17: 0.009 | O17: 0.006
A18: NF | B18: 0.035 | C18: 0.012 | D18: 0.027 | E18: 0.022 | F18: 0.016 | G18: 0.006 | I18: NF | J18: 0.033 | K18: 0.014 | L18: 0.029 | M18: 0.023 | N18: 0.015 | O18: 0.01
A19: BO+ | B19: 0.074 | C19: 0.016 | D19: 0.018 | E19: 0.015 | F19: 0.011 | G19: 0.025 | I19: BO+ | J19: 0.033 | K19: 0.014 | L19: 0.027 | M19: 0.022 | N19: 0.015 | O19: 0.009
A20: CN+ | B20: 0.095 | C20: 0.036 | D20: 0.03 | E20: 0.026 | F20: 0.034 | G20: 0.044 | I20: CN+ | J20: 0.126 | K20: 0.014 | L20: 0.024 | M20: 0.016 | N20: 0.032 | O20: 0.018
A21: O2 | B21: 0.021 | C21: 0.009 | D21: 0.017 | E21: 0.014 | F21: 0.012 | G21: 0.006 | I21: O2 | J21: 0.024 | K21: 0.009 | L21: 0.017 | M21: 0.012 | N21: 0.008 | O21: 0.005
A22: NH | B22: 0.01 | C22: 0.012 | D22: 0.024 | E22: 0.019 | F22: 0.014 | G22: 0.006 | I22: NH | J22: 0.014 | K22: 0.012 | L22: 0.02 | M22: 0.014 | N22: 0.006 | O22: 0.008
B24: RCCSD(T)/cc-pVTZ | Frobenius ||Fov||^2 S=0 | J24: UCCSD(T)/cc-pVTZ | Frobenius ||Fov||^2 Alpha S=1
B25: HF | C25: B3LYP | D25: LDA | E25: revPBE | F25: SCAN | G25: SCAN0 | J25: HF | K25: B3LYP | L25: LDA | M25: revPBE | N25: SCAN | O25: SCAN0
A26: BN | B26: 0 | C26: 0.162 | D26: 0.28 | E26: 0.162 | F26: 0.131 | G26: 0.099 | I26: BN | J26: 0 | K26: 0.153 | L26: 0.276 | M26: 0.15 | N26: 0.127 | O26: 0.0962
A27: C2 | B27: 0 | C27: 0.161 | D27: 0.294 | E27: 0.201 | F27: 0.13 | G27: 0.099 | I27: C2 | J27: 0 | K27: 0.153 | L27: 0.271 | M27: 0.149 | N27: 0.125 | O27: 0.0945
A28: CH2 | B28: 0 | C28: 0.109 | D28: 0.193 | E28: 0.112 | F28: 0.0897 | G28: 0.0684 | I28: CH2 | J28: 0 | K28: 0.11 | L28: 0.191 | M28: 0.107 | N28: 0.0902 | O28: 0.0681
A29: NF | B29: 0 | C29: 0.211 | D29: 0.374 | E29: 0.213 | F29: 0.186 | G29: 0.14 | I29: NF | J29: 0 | K29: 0.2 | L29: 0.363 | M29: 0.194 | N29: 0.176 | O29: 0.133
A30: BO+ | B30: 0 | C30: 0.176 | D30: 0.308 | E30: 0.18 | F30: 0.145 | G30: 0.109 | I30: BO+ | J30: 0 | K30: 0.165 | L30: 0.303 | M30: 0.166 | N30: 0.141 | O30: 0.106
A31: CN+ | B31: 0 | C31: 0.182 | D31: 0.309 | E31: 0.185 | F31: 0.149 | G31: 0.113 | I31: CN+ | J31: 0 | K31: 0.171 | L31: 0.301 | M31: 0.17 | N31: 0.144 | O31: 0.109
A32: O2 | B32: 0 | C32: 0.215 | D32: 0.382 | E32: 0.229 | F32: 0.205 | G32: 0.141 | I32: O2 | J32: 0 | K32: 0.198 | L32: 0.359 | M32: 0.189 | N32: 0.174 | O32: 0.131
A33: NH | B33: 0 | C33: 0.122 | D33: 0.23 | E33: 0.13 | F33: 0.105 | G33: 0.0759 | I33: NH | J33: 0 | K33: 0.122 | L33: 0.219 | M33: 0.113 | N33: 0.1 | O33: 0.0753
J36: UCCSD(T)/cc-pVTZ | Frobenius ||Fov||^2 Beta S=1
J37: HF | K37: B3LYP | L37: LDA | M37: revPBE | N37: SCAN | O37: SCAN0
I38: BN | J38: 0 | K38: 0.15 | L38: 0.27 | M38: 0.15 | N38: 0.116 | O38: 0.0889
I39: C2 | J39: 0 | K39: 0.15 | L39: 0.265 | M39: 0.15 | N39: 0.117 | O39: 0.089
I40: CH2 | J40: 0 | K40: 0.108 | L40: 0.189 | M40: 0.109 | N40: 0.0791 | O40: 0.0616
I41: NF | J41: 0 | K41: 0.22 | L41: 0.379 | M41: 0.223 | N41: 0.184 | O41: 0.139
I42: BO+ | J42: 0 | K42: 0.162 | L42: 0.297 | M42: 0.163 | N42: 0.127 | O42: 0.0982
I43: CN+ | J43: 0 | K43: 0.168 | L43: 0.296 | M43: 0.17 | N43: 0.131 | O43: 0.0995
I44: O2 | J44: 0 | K44: 0.231 | L44: 0.385 | M44: 0.23 | N44: 0.191 | O44: 0.145
I45: NH | J45: 0 | K45: 0.121 | L45: 0.219 | M45: 0.117 | N45: 0.0892 | O45: 0.0691

Sheet SFigure33-38
A1: BN | B1: ha | C1: ha | D1: ev | E1: ev (theory) | G1: ev (exp) | I1: singlet | J1: triplet | K1: singlet | L1: triplet | P1: theory | Q1: exp
A2: CCSD(T)/cc-PVTZ | B2: singlet | C2: triplet gs | D2: gap | E2: RMR CCSD(T) A | F2: sgn err | G2: exp | H2: sgn err | I2: S^2 HF | J2: S^2 HF | K2: S^2 CC | L2: S^2 CC | M2: alpha | N2: AP singlet | O2: AP Gap | P2: sgn err | Q2: sgn err
A3: hf | B3: -79.25434 | C3: -79.266908 | D3: =(B3-C3)*27.2114 -> 0.34198879 | E3: 0.05232 | F3: =D3-E3 -> 0.28966879 | G3: 0.01897 | H3: =D3-G3 -> 0.32301879 | I3: 1.2995652 | J3: 2.0555425 | K3: 0.410818 | L3: 2.001046 | M3: =(L3-0)/(L3-K3) -> 1.2583391 | N3: =(M3*B3)+(1-M3)*C3 -> -79.251093 | O3: =(N3-C3)*27.2114 -> 0.43033786 | P3: =O3-E3 -> 0.37801786 | Q3: =O3-G3 -> 0.41136786
A4: b3lyp | B4: -79.253838 | C4: -79.2655 | D4: =(B4-C4)*27.2114 -> 0.31732084 | E4: 0.05232 | F4: =D4-E4 -> 0.26500084 | G4: 0.01897 | H4: =D4-G4 -> 0.29835084 | I4: 1.0129081 | J4: 2.0033324 | K4: 1.159447 | L4: 2.000868 | M4: =(L4-0)/(L4-K4) -> 2.377963 | N4: =(M4*B4)+(1-M4)*C4 -> -79.237769 | O4: =(N4-C4)*27.2114 -> 0.75457722 | P4: =O4-E4 -> 0.70225722 | Q4: =O4-G4 -> 0.73560722
A5: lda | B5: -79.255357 | C5: -79.25932 | D5: =(B5-C5)*27.2114 -> 0.10784096 | E5: 0.05232 | F5: =D5-E5 -> 0.055520955 | G5: 0.01897 | H5: =D5-G5 -> 0.088870955 | I5: 0.48668881 | J5: 2.0024669 | K5: 0.625812 | L5: 2.000903 | M5: =(L5-0)/(L5-K5) -> 1.4551059 | N5: =(M5*B5)+(1-M5)*C5 -> -79.253554 | O5: =(N5-C5)*27.2114 -> 0.15692001 | P5: =O5-E5 -> 0.10460001 | Q5: =O5-G5 -> 0.13795001
A6: revPBE | B6: -79.258049 | C6: -79.265345 | D6: =(B6-C6)*27.2114 -> 0.19853437 | E6: 0.05232 | F6: =D6-E6 -> 0.14621437 | G6: 0.01897 | H6: =D6-G6 -> 0.17956437 | I6: 0.78249442 | J6: 2.0038526 | K6: 0.982528 | L6: 2.000914 | M6: =(L6-0)/(L6-K6) -> 1.9647894 | N6: =(M6*B6)+(1-M6)*C6 -> -79.25101 | O6: =(N6-C6)*27.2114 -> 0.39007823 | P6: =O6-E6 -> 0.33775823 | Q6: =O6-G6 -> 0.37110823
A7: SCAN | B7: -79.254205 | C7: -79.265948 | D7: =(B7-C7)*27.2114 -> 0.31953476 | E7: 0.05232 | F7: =D7-E7 -> 0.26721476 | G7: 0.01897 | H7: =D7-G7 -> 0.30056476 | I7: 1.0224172 | J7: 2.0061466 | K7: 1.154445 | L7: 2.000904 | M7: =(L7-0)/(L7-K7) -> 2.3638522 | N7: =(M7*B7)+(1-M7)*C7 -> -79.23819 | O7: =(N7-C7)*27.2114 -> 0.75533296 | P7: =O7-E7 -> 0.70301296 | Q7: =O7-G7 -> 0.73636296
A8: SCAN0 | B8: -79.254654 | C8: -79.266413 | D8: =(B8-C8)*27.2114 -> 0.31996851 | E8: 0.05232 | F8: =D8-E8 -> 0.26764851 | G8: 0.01897 | H8: =D8-G8 -> 0.30099851 | I8: 1.0275872 | J8: 2.0069675 | K8: 1.153071 | L8: 2.000896 | M8: =(L8-0)/(L8-K8) -> 2.3600342 | N8: =(M8*B8)+((1-M8)*C8) -> -79.238662 | O8: =(N8-C8)*27.2114 -> 0.75513663 | P8: =O8-E8 -> 0.70281663 | Q8: =O8-G8 -> 0.73616663
A10: C2 | B10: ha | C10: ha | D10: ev | E10: ev (theory) | G10: ev (exp) | I10: singlet | J10: triplet | K10: singlet | L10: triplet | P10: theory | Q10: exp
A11: CCSD(T)/cc-PVTZ | B11: singlet gs | C11: triplet | D11: gap | E11: RMR CCSD(T) A | F11: sgn err | G11: exp | H11: sgn err | I11: S^2 HF | J11: S^2 HF | K11: S^2 CC | L11: S^2 CC | M11: alpha | N11: AP singlet | O11: AP Gap | P11: sgn err | Q11: sgn err
A12: hf | B12: -75.76829 | C12: -75.777055 | D12: =(C12-B12)*27.2114 -> -0.23852479 | E12: 0.1215 | F12: =D12-E12 -> -0.36002479 | G12: 0.08877 | H12: =D12-G12 -> -0.32729479 | I12: 1.6976357 | J12: 2.2525044 | K12: 0.530364 | L12: 1.999986 | M12: =(L12-0)/(L12-K12) -> 1.3608846 | N12: =(M12*B12)+(1-M12)*C12 -> -75.765126 | O12: =(C12-N12)*27.2114 -> -0.32460472 | P12: =O12-E12 -> -0.44610472 | Q12: =O12-G12 -> -0.41337472
A13: b3lyp | B13: -75.772719 | C13: -75.777948 | D13: =(C13-B13)*27.2114 -> -0.1423012 | E13: 0.1215 | F13: =D13-E13 -> -0.2638012 | G13: 0.08877 | H13: =D13-G13 -> -0.2310712 | I13: 0.76724251 | J13: 2.0041844 | K13: 0.364842 | L13: 2.001337 | M13: =(L13-0)/(L13-K13) -> 1.2229411 | N13: =(M13*B13)+(1-M13)*C13 -> -75.771553 | O13: =(C13-N13)*27.2114 -> -0.17402599 | P13: =O13-E13 -> -0.29552599 | Q13: =O13-G13 -> -0.26279599
A14: lda | B14: -75.773287 | C14: -75.771562 | D14: =(C14-B14)*27.2114 -> 0.046954631 | E14: 0.1215 | F14: =D14-E14 -> -0.074545369 | G14: 0.08877 | H14: =D14-G14 -> -0.041815369 | I14: 0.73711197 | J14: 2.0022607 | K14: 0.451519 | L14: 2.00136 | M14: =(L14-0)/(L14-K14) -> 1.2913325 | N14: =(M14*B14)+(1-M14)*C14 -> -75.77379 | O14: =(C14-N14)*27.2114 -> 0.06063404 | P14: =O14-E14 -> -0.06086596 | Q14: =O14-G14 -> -0.02813596
A15: revPBE | B15: -75.778793 | C15: -75.77783 | D15: =(C15-B15)*27.2114 -> 0.026186347 | E15: 0.1215 | F15: =D15-E15 -> -0.095313653 | G15: 0.08877 | H15: =D15-G15 -> -0.062583653 | I15: 0.88976841 | J15: 2.002945 | K15: 0.505521 | L15: 2.001373 | M15: =(L15-0)/(L15-K15) -> 1.3379485 | N15: =(M15*B15)+(1-M15)*C15 -> -75.779118 | O15: =(C15-N15)*27.2114 -> 0.035035984 | P15: =O15-E15 -> -0.086464016 | Q15: =O15-G15 -> -0.053734016
A16: SCAN | B16: -75.778843 | C16: -75.778346 | D16: =(C16-B16)*27.2114 -> 0.013538488 | E16: 0.1215 | F16: =D16-E16 -> -0.10796151 | G16: 0.08877 | H16: =D16-G16 -> -0.075231512 | I16: 1.0322268 | J16: 2.005371 | K16: 0.539872 | L16: 2.001393 | M16: =(L16-0)/(L16-K16) -> 1.3693905 | N16: =(M16*B16)+(1-M16)*C16 -> -75.779027 | O16: =(C16-N16)*27.2114 -> 0.018539477 | P16: =O16-E16 -> -0.10296052 | Q16: =O16-G16 -> -0.070230523
A17: SCAN0 | B17: -75.771121 | C17: -75.778865 | D17: =(C17-B17)*27.2114 -> -0.21073488 | E17: 0.1215 | F17: =D17-E17 -> -0.33223488 | G17: 0.08877 | H17: =D17-G17 -> -0.29950488 | I17: 1.0808446 | J17: 2.0069735 | K17: 0.435658 | L17: 2.001339 | M17: =(L17-0)/(L17-K17) -> 1.2782546 | N17: =(M17*B17)+((1-M17)*C17) -> -75.768966 | O17: =(C17-N17)*27.2114 -> -0.26937283 | P17: =O17-E17 -> -0.39087283 | Q17: =O17-G17 -> -0.35814283
P18: improv w/ks
P19: not better than RHF-CC
A21: CH2 | B21: ha | C21: ha | D21: ev | E21: ev (theory) | G21: ev (exp) | I21: singlet | J21: triplet | K21: singlet | L21: triplet | P21: theory | Q21: exp
A22: CCSD(T)/cc-PVTZ | B22: singlet | C22: triplet gs | D22: gap | E22: MRBWCCSDT/tz | F22: sgn err | G22: exp | H22: sgn err | I22: S^2 HF | J22: S^2 HF | K22: S^2 CC | L22: S^2 CC | M22: alpha | N22: AP singlet | O22: AP Gap | P22: sgn err | Q22: sgn err
A23: hf | B23: -39.060714 | C23: -39.077097 | D23: =(B23-C23)*27.2114 -> 0.44579865 | E23: =(10.18/627.5)*27.2114 -> 0.44145347 | F23: =D23-E23 -> 0.0043451825 | G23: =(8.99/627.5)*27.2114 -> 0.38984938 | H23: =D23-G23 -> 0.055949272 | I23: 0.72053041 | J23: 2.0162747 | K23: 0.499528 | L23: 2.000363 | M23: =(L23-0)/(L23-K23) -> 1.3328334 | N23: =(M23*B23)+(1-M23)*C23 -> -39.055261 | O23: =(N23-C23)*27.2114 -> 0.59417533 | P23: =O23-E23 -> 0.15272186 | Q23: =O23-G23 -> 0.20432595
A24: b3lyp | B24: -39.059912 | C24: -39.076262 | D24: =(B24-C24)*27.2114 -> 0.44489605 | E24: =(10.18/627.5)*27.2114 -> 0.44145347 | F24: =D24-E24 -> 0.0034425803 | G24: =(8.99/627.5)*27.2114 -> 0.38984938 | H24: =D24-G24 -> 0.05504667 | I24: 0.58387233 | J24: 2.0052577 | K24: 0.49125 | L24: 2.000295 | M24: =(L24-0)/(L24-K24) -> 1.325537 | N24: =(M24*B24)+(1-M24)*C24 -> -39.05459 | O24: =(N24-C24)*27.2114 -> 0.58972618 | P24: =O24-E24 -> 0.14827271 | Q24: =O24-G24 -> 0.1998768
A25: lda | B25: -39.056763 | C25: -39.073187 | D25: =(B25-C25)*27.2114 -> 0.44691704 | E25: =(10.18/627.5)*27.2114 -> 0.44145347 | F25: =D25-E25 -> 0.005463571 | G25: =(8.99/627.5)*27.2114 -> 0.38984938 | H25: =D25-G25 -> 0.05706766 | I25: 0.55009184 | J25: 2.0045606 | K25: 0.489748 | L25: 2.000291 | M25: =(L25-0)/(L25-K25) -> 1.3242198 | N25: =(M25*B25)+(1-M25)*C25 -> -39.051438 | O25: =(N25-C25)*27.2114 -> 0.59181641 | P25: =O25-E25 -> 0.15036294 | Q25: =O25-G25 -> 0.20196703
A26: revPBE | B26: -39.05983 | C26: -39.076172 | D26: =(B26-C26)*27.2114 -> 0.44468734 | E26: =(10.18/627.5)*27.2114 -> 0.44145347 | F26: =D26-E26 -> 0.0032338689 | G26: =(8.99/627.5)*27.2114 -> 0.38984938 | H26: =D26-G26 -> 0.054837958 | I26: 0.65597194 | J26: 2.0061207 | K26: 0.495403 | L26: 2.000301 | M26: =(L26-0)/(L26-K26) -> 1.3291937 | N26: =(M26*B26)+(1-M26)*C26 -> -39.05445 | O26: =(N26-C26)*27.2114 -> 0.59107563 | P26: =O26-E26 -> 0.14962216 | Q26: =O26-G26 -> 0.20122625
A27: SCAN | B27: -39.060105 | C27: -39.076498 | D27: =(B27-C27)*27.2114 -> 0.44607621 | E27: =(10.18/627.5)*27.2114 -> 0.44145347 | F27: =D27-E27 -> 0.0046227388 | G27: =(8.99/627.5)*27.2114 -> 0.38984938 | H27: =D27-G27 -> 0.056226828 | I27: 0.74440758 | J27: 2.0101045 | K27: 0.505816 | L27: 2.000325 | M27: =(L27-0)/(L27-K27) -> 1.3384496 | N27: =(M27*B27)+(1-M27)*C27 -> -39.054557 | O27: =(N27-C27)*27.2114 -> 0.59705053 | P27: =O27-E27 -> 0.15559706 | Q27: =O27-G27 -> 0.20720115
A28: SCAN0 | B28: -39.060366 | C28: -39.076753 | D28: =(B28-C28)*27.2114 -> 0.44593117 | E28: =(10.18/627.5)*27.2114 -> 0.44145347 | F28: =D28-E28 -> 0.004477702 | G28: =(8.99/627.5)*27.2114 -> 0.38984938 | H28: =D28-G28 -> 0.056081791 | I28: 0.74398347 | J28: 2.010212 | K28: 0.504782 | L28: 2.000328 | M28: =(L28-0)/(L28-K28) -> 1.3375236 | N28: =(M28*B28)+((1-M28)*C28) -> -39.054834 | O28: =(N28-C28)*27.2114 -> 0.59644344 | P28: =O28-E28 -> 0.15498998 | Q28: =O28-G28 -> 0.20659406
P29: no improv w/ks
P30: not better than RHF-CC
A32: NF | B32: ha | C32: ha | D32: ev | E32: ev (theory) | G32: ev (exp) | I32: singlet | J32: triplet | K32: singlet | L32: triplet | P32: theory | Q32: exp
A33: CCSD(T)/cc-PVTZ | B33: singlet | C33: triplet gs | D33: gap | E33: MRBWCCSDT-α/tz | F33: sgn err | G33: exp | H33: sgn err | I33: S^2 HF | J33: S^2 HF | K33: S^2 CC | L33: S^2 CC | M33: alpha | N33: AP singlet | O33: AP Gap | P33: sgn err | Q33: sgn err
A34: hf | B34: -154.23115 | C34: -154.24907 | D34: =(B34-C34)*27.2114 -> 0.48753468 | E34: 1.53121 | F34: =D34-E34 -> -1.0436753 | G34: 1.41776 | H34: =D34-G34 -> -0.93022532 | I34: 1.0135781 | J34: 2.0215005 | K34: 1.384459 | L34: 2.000777 | M34: =(L34-0)/(L34-K34) -> 3.2463387 | N34: =(M34*B34)+(1-M34)*C34 -> -154.1909 | O34: =(N34-C34)*27.2114 -> 1.5827027 | P34: =O34-E34 -> 0.051492722 | Q34: =O34-G34 -> 0.16494272
A35: b3lyp | B35: -154.23074 | C35: -154.24801 | D35: =(B35-C35)*27.2114 -> 0.4701319 | E35: 1.53121 | F35: =D35-E35 -> -1.0610781 | G35: 1.41776 | H35: =D35-G35 -> -0.9476281 | I35: 1.0042751 | J35: 2.0064558 | K35: 1.397691 | L35: 2.000806 | M35: =(L35-0)/(L35-K35) -> 3.3174536 | N35: =(M35*B35)+(1-M35)*C35 -> -154.1907 | O35: =(N35-C35)*27.2114 -> 1.5596407 | P35: =O35-E35 -> 0.028430749 | Q35: =O35-G35 -> 0.14188075
A36: lda | B36: -154.22519 | C36: -154.24197 | D36: =(B36-C36)*27.2114 -> 0.45665274 | E36: 1.53121 | F36: =D36-E36 -> -1.0745573 | G36: 1.41776 | H36: =D36-G36 -> -0.96110726 | I36: 1.0013839 | J36: 2.0037617 | K36: 1.408561 | L36: 2.000839 | M36: =(L36-0)/(L36-K36) -> 3.3782092 | N36: =(M36*B36)+(1-M36)*C36 -> -154.18528 | O36: =(N36-C36)*27.2114 -> 1.5426685 | P36: =O36-E36 -> 0.01145848 | Q36: =O36-G36 -> 0.12490848
A37: revPBE | B37: -154.23096 | C37: -154.24815 | D37: =(B37-C37)*27.2114 -> 0.46791009 | E37: 1.53121 | F37: =D37-E37 -> -1.0632999 | G37: 1.41776 | H37: =D37-G37 -> -0.94984991 | I37: 1.0035871 | J37: 2.0049006 | K37: 1.397011 | L37: 2.000828 | M37: =(L37-0)/(L37-K37) -> 3.3136331 | N37: =(M37*B37)+(1-M37)*C37 -> -154.19117 | O37: =(N37-C37)*27.2114 -> 1.5504824 | P37: =O37-E37 -> 0.019272368 | Q37: =O37-G37 -> 0.13272237
A38: SCAN | B38: -154.2307 | C38: -154.2483 | D38: =(B38-C38)*27.2114 -> 0.47887792 | E38: 1.53121 | F38: =D38-E38 -> -1.0523321 | G38: 1.41776 | H38: =D38-G38 -> -0.93888208 | I38: 1.0066181 | J38: 2.0116928 | K38: 1.388949 | L38: 2.000822 | M38: =(L38-0)/(L38-K38) -> 3.2699956 | N38: =(M38*B38)+(1-M38)*C38 -> -154.19076 | O38: =(N38-C38)*27.2114 -> 1.5659287 | P38: =O38-E38 -> 0.034718671 | Q38: =O38-G38 -> 0.14816867
A39: SCAN0 | B39: -154.23097 | C39: -154.24866 | D39: =(B39-C39)*27.2114 -> 0.48123334 | E39: 1.53121 | F39: =D39-E39 -> -1.0499767 | G39: 1.41776 | H39: =D39-G39 -> -0.93652666 | I39: 1.0079824 | J39: 2.0133988 | K39: 1.388867 | L39: 2.000799 | M39: =(L39-0)/(L39-K39) -> 3.2696427 | N39: =(M39*B39)+((1-M39)*C39) -> -154.19083 | O39: =(N39-C39)*27.2114 -> 1.5734611 | P39: =O39-E39 -> 0.04225107 | Q39: =O39-G39 -> 0.15570107
P40: improv w/ks
P41: better than RHF-CC
A43: BO+ | B43: ha | C43: ha | D43: ev | E43: ev (theory) | G43: ev (exp) | I43: singlet | J43: triplet | K43: singlet | L43: triplet | P43: theory | Q43: exp
A44: CCSD(T)/cc-PVTZ | B44: singlet gs | C44: triplet | D44: gap | E44: CMRCI/tz | F44: sgn err | G44: none | H44: sgn err | I44: S^2 HF | J44: S^2 HF | K44: S^2 CC | L44: S^2 CC | M44: alpha | N44: AP singlet | O44: AP Gap | P44: sgn err | Q44: sgn err
...

Sheet SFigure39-45
B2: UCCSD(T)/cc-pVTZ | ST or TS Gap (eV) | J2: UCCSD(T)/cc-pVTZ | Signed Errors (eV) versus Theoretical reference data
B3: HF | C3: B3LYP | D3: LDA | E3: revPBE | F3: SCAN | G3: SCAN0 | J3: HF | K3: B3LYP | L3: LDA | M3: revPBE | N3: SCAN | O3: SCAN0
A4: BN | B4: 0.342 | C4: 0.3173 | D4: 0.1078 | E4: 0.1985 | F4: 0.3195 | G4: 0.32 | I4: BN | J4: 0.29 | K4: 0.265 | L4: 0.056 | M4: 0.146 | N4: 0.267 | O4: 0.268
A5: C2 | B5: -0.2385 | C5: -0.1423 | D5: 0.047 | E5: 0.0262 | F5: 0.0135 | G5: -0.2107 | I5: C2 | J5: -0.36 | K5: -0.264 | L5: -0.075 | M5: -0.095 | N5: -0.108 | O5: -0.332
A6: CH2 | B6: 0.4458 | C6: 0.4449 | D6: 0.4469 | E6: 0.4447 | F6: 0.4461 | G6: 0.4459 | I6: CH2 | J6: 0.004 | K6: 0.003 | L6: 0.005 | M6: 0.003 | N6: 0.005 | O6: 0.004
A7: NF | B7: 0.4875 | C7: 0.4701 | D7: 0.4567 | E7: 0.4679 | F7: 0.4789 | G7: 0.4812 | I7: NF | J7: -1.044 | K7: -1.061 | L7: -1.075 | M7: -1.063 | N7: -1.052 | O7: -1.05
A8: BO+ | B8: -0.4428 | C8: 0.5303 | D8: 0.5456 | E8: 0.5326 | F8: 0.5123 | G8: 0.5093 | I8: BO+ | J8: -0.987 | K8: -0.014 | L8: 0.001 | M8: -0.012 | N8: -0.032 | O8: -0.035
A9: CN+ | B9: -0.2834 | C9: -0.1469 | D9: 0.0874 | E9: 0.0677 | F9: -0.1995 | G9: -0.2249 | I9: CN+ | J9: -0.382 | K9: -0.246 | L9: -0.012 | M9: -0.031 | N9: -0.299 | O9: -0.324
A10: O2 | B10: 0.4789 | C10: 0.4406 | D10: 0.4383 | E10: 0.4396 | F10: 0.4432 | G10: 0.4437 | I10: O2 | J10: -0.61 | K10: -0.648 | L10: -0.651 | M10: -0.649 | N10: -0.646 | O10: -0.645
A11: NH | B11: 0.4327 | C11: 0.405 | D11: 0.3889 | E11: 0.4063 | F11: 0.423 | G11: 0.4241 | I11: NH | J11: -1.345 | K11: -1.373 | L11: -1.389 | M11: -1.372 | N11: -1.355 | O11: -1.354
B13: AP-UCCSD(T)/cc-pVTZ | ST or TS Gap (eV) | J13: AP-UCCSD(T)/cc-pVTZ | Signed Errors (eV) versus Theoretical reference data
B14: HF | C14: B3LYP | D14: LDA | E14: revPBE | F14: SCAN | G14: SCAN0 | J14: HF | K14: B3LYP | L14: LDA | M14: revPBE | N14: SCAN | O14: SCAN0
A15: BN | B15: 0.43033786 | C15: 0.75457722 | D15: 0.15692001 | E15: 0.39007823 | F15: 0.75533296 | G15: 0.75513663 | I15: BN | J15: 0.378 | K15: 0.7023 | L15: 0.1046 | M15: 0.3378 | N15: 0.703 | O15: 0.7028
A16: C2 | B16: -0.32460472 | C16: -0.17402599 | D16: 0.06063404 | E16: 0.035035984 | F16: 0.018539477 | G16: -0.26937283 | I16: C2 | J16: -0.4461 | K16: -0.2955 | L16: -0.0609 | M16: -0.0865 | N16: -0.103 | O16: -0.3909
A17: CH2 | B17: 0.59417533 | C17: 0.58972618 | D17: 0.59181641 | E17: 0.59107563 | F17: 0.59705053 | G17: 0.59644344 | I17: CH2 | J17: 0.1527 | K17: 0.1483 | L17: 0.1504 | M17: 0.1496 | N17: 0.1556 | O17: 0.155
A18: NF | B18: 1.5827027 | C18: 1.5596407 | D18: 1.5426685 | E18: 1.5504824 | F18: 1.5659287 | G18: 1.5734611 | I18: NF | J18: 0.0515 | K18: 0.0284 | L18: 0.0115 | M18: 0.0193 | N18: 0.0347 | O18: 0.0423
A19: BO+ | B19: -0.97033562 | C19: 0.5298976 | D19: 0.54561497 | E19: 0.53228448 | F19: 0.5110086 | G19: 0.50746546 | I19: BO+ | J19: -1.5148 | K19: -0.0146 | L19: 0.0011 | M19: -0.0122 | N19: -0.0335 | O19: -0.037
A20: CN+ | B20: -0.37623853 | C20: -0.18781294 | D20: 0.10304385 | E20: 0.081849932 | F20: -0.24657493 | G20: -0.28208009 | I20: CN+ | J20: -0.4753 | K20: -0.2868 | L20: 0.004 | M20: -0.0172 | N20: -0.3456 | O20: -0.3811
A21: O2 | B21: 1.1688143 | C21: 1.0849959 | D21: 1.0868352 | E21: 1.0850399 | F21: 1.089064 | G21: 1.087177 | I21: O2 | J21: 0.08 | K21: -0.004 | L21: -0.002 | M21: -0.004 | N21: 0 | O21: -0.002
A22: NH | B22: 1.8327988 | C22: 1.8256274 | D22: 1.8202105 | E22: 1.8241553 | F22: 1.8358177 | G22: 1.8358591 | I22: NH | J22: 0.055 | K22: 0.048 | L22: 0.042 | M22: 0.046 | N22: 0.058 | O22: 0.058
B24: UCCSD(T)/cc-pVTZ | T1 Diagnostic S=0 | J24: UCCSD(T)/cc-pVTZ | T1 Diagnostic S=1
B25: HF | C25: B3LYP | D25: LDA | E25: revPBE | F25: SCAN | G25: SCAN0 | J25: HF | K25: B3LYP | L25: LDA | M25: revPBE | N25: SCAN | O25: SCAN0
A26: BN | B26: 0.141 | C26: 0.019 | D26: 0.05 | E26: 0.027 | F26: 0.018 | G26: 0.011 | I26: BN | J26: 0.064 | K26: 0.015 | L26: 0.028 | M26: 0.019 | N26: 0.012 | O26: 0.015
A27: C2 | B27: 0.144 | C27: 0.039 | D27: 0.126 | E27: 0.146 | F27: 0.169 | G27: 0.067 | I27: C2 | J27: 0.168 | K27: 0.012 | L27: 0.019 | M27: 0.012 | N27: 0.01 | O27: 0.009
A28: CH2 | B28: 0.052 | C28: 0.022 | D28: 0.023 | E28: 0.038 | F28: 0.059 | G28: 0.059 | I28: CH2 | J28: 0.013 | K28: 0.013 | L28: 0.021 | M28: 0.011 | N28: 0.009 | O28: 0.006
A29: NF | B29: 0.033 | C29: 0.014 | D29: 0.031 | E29: 0.022 | F29: 0.012 | G29: 0.006 | I29: NF | J29: 0.033 | K29: 0.014 | L29: 0.029 | M29: 0.023 | N29: 0.015 | O29: 0.01
A30: BO+ | B30: 0.026 | C30: 0.046 | D30: 0.018 | E30: 0.054 | F30: 0.081 | G30: 0.079 | I30: BO+ | J30: 0.032977265 | K30: 0.013693064 | L30: 0.027156951 | M30: 0.022079402 | N30: 0.015 | O30: 0.0093541435
A31: CN+ | B31: 0.145 | C31: 0.326 | D31: 0.133 | E31: 0.158 | F31: 0.055 | G31: 0.073 | I31: CN+ | J31: 0.126 | K31: 0.014 | L31: 0.024 | M31: 0.016 | N31: 0.018 | O31: 0.032
A32: O2 | B32: 0.103 | C32: 0.009 | D32: 0.016 | E32: 0.01 | F32: 0.007 | G32: 0.006 | I32: O2 | J32: 0.024 | K32: 0.009 | L32: 0.017 | M32: 0.012 | N32: 0.008 | O32: 0.005
A33: NH | B33: 0.009 | C33: 0.014 | D33: 0.022 | E33: 0.015 | F33: 0.008 | G33: 0.006 | I33: NH | J33: 0.014 | K33: 0.012 | L33: 0.02 | M33: 0.014 | N33: 0.008 | O33: 0.006
B35: UCCSD(T)/cc-pVTZ | Frobenius ||Fov||^2 Alpha S=0 | J35: UCCSD(T)/cc-pVTZ | Frobenius ||Fov||^2 Alpha S=1
B36: HF | C36: B3LYP | D36: LDA | E36: revPBE | F36: SCAN | G36: SCAN0 | J36: HF | K36: B3LYP | L36: LDA | M36: revPBE | N36: SCAN | O36: SCAN0
A37: BN | B37: 0 | C37: 0.157 | D37: 0.282 | E37: 0.161 | F37: 0.118 | G37: 0.0903 | I37: BN | J37: 0 | K37: 0.153 | L37: 0.276 | M37: 0.15 | N37: 0.127 | O37: 0.0962
A38: C2 | B38: 0 | C38: 0.158 | D38: 0.279 | E38: 0.161 | F38: 0.127 | G38: 0.0926 | I38: C2 | J38: 0 | K38: 0.153 | L38: 0.271 | M38: 0.149 | N38: 0.125 | O38: 0.0945
A39: CH2 | B39: 0 | C39: 0.11 | D39: 0.194 | E39: 0.11 | F39: 0.089 | G39: 0.0682 | I39: CH2 | J39: 0 | K39: 0.11 | L39: 0.191 | M39: 0.107 | N39: 0.0902 | O39: 0.0681
A40: NF | B40: 0 | C40: 0.211 | D40: 0.376 | E40: 0.21 | F40: 0.183 | G40: 0.138 | I40: NF | J40: 0 | K40: 0.2 | L40: 0.363 | M40: 0.194 | N40: 0.176 | O40: 0.133
A41: BO+ | B41: 0 | C41: 0.176 | D41: 0.308 | E41: 0.18 | F41: 0.145 | G41: 0.109 | I41: BO+ | J41: 0 | K41: 0.165 | L41: 0.303 | M41: 0.166 | N41: 0.141 | O41: 0.106
A42: CN+ | B42: 0 | C42: 0.179 | D42: 0.31 | E42: 0.183 | F42: 0.147 | G42: 0.102 | I42: CN+ | J42: 0 | K42: 0.171 | L42: 0.301 | M42: 0.17 | N42: 0.144 | O42: 0.109
A43: O2 | B43: 0 | C43: 0.216 | D43: 0.375 | E43: 0.212 | F43: 0.186 | G43: 0.14 | I43: O2 | J43: 0 | K43: 0.198 | L43: 0.359 | M43: 0.189 | N43: 0.174 | O43: 0.131
A44: NH | B44: 0 | C44: 0.124 | D44: 0.226 | E44: 0.118 | F44: 0.0967 | G44: 0.0736 | I44: NH | J44: 0 | K44: 0.122 | L44: 0.219 | M44: 0.113 | N44: 0.1 | O44: 0.0753
...

Sheet SFigure7-Data-1
A1: HF | B1: orb | C1: kt | D1: d2 | E1: kt | F1: d2 | G1: ps | H1: p3 | I1: p3 | J1: ps | K1: p3+ | L1: p3+ | M1: ps | N1: exp | O1: sgn err kt | P1: sgn err d2 | Q1: sgn err p3 | R1: sgn err p3+
A2: n2 | B2: 3sgg | C2: -0.63291374 | D2: -0.55366482 | E2: =C2*27.2114 -> -17.222469 | F2: =D2*27.2114 -> -15.065995 | G2: 0.88387124 | H2: -0.58635967 | I2: =H2*27.2114 -> -15.955667 | J2: 0.90743298 | K2: -0.58027696 | L2: =K2*27.2114 -> -15.790148 | M2: 0.90284026 | N2: 15.58 | O2: =-E2-N2 -> 1.6424688 | P2: =-F2-N2 -> -0.51400522 | Q2: =-I2-N2 -> 0.37566747 | R2: =-L2-N2 -> 0.21014842
B3: 1piu | C3: -0.61194717 | D3: -0.63049395 | E3: =C3*27.2114 -> -16.651939 | F3: =D3*27.2114 -> -17.156623 | G3: 0.91478261 | H3: -0.63598608 | I3: =H3*27.2114 -> -17.306072 | J3: 0.91763347 | K3: -0.63542917 | L3: =K3*27.2114 -> -17.290917 | M3: 0.91734303 | N3: 16.93 | O3: =-E3-N3 -> -0.27806073 | P3: =-F3-N3 -> 0.22662318 | Q3: =-I3-N3 -> 0.37607169 | R3: =-L3-N3 -> 0.36091734
B4: 2sgu | C4: -0.77899787 | D4: -0.66792018 | E4: =C4*27.2114 -> -21.197623 | F4: =D4*27.2114 -> -18.175043 | G4: 0.84752485 | H4: -0.7068641 | I4: =H4*27.2114 -> -19.234762 | J4: 0.87860216 | K4: -0.69877655 | L4: =K4*27.2114 -> -19.014688 | M4: 0.87168268 | N4: 19.75 | O4: =-E4-N4 -> 1.4476225 | P4: =-F4-N4 -> -1.5749568 | Q4: =-I4-N4 -> -0.51523812 | R4: =-L4-N4 -> -0.73531181
A5: h2o | B5: 1b1 | C5: -0.5031622 | D5: -0.41071833 | E5: =C5*27.2114 -> -13.691748 | F5: =D5*27.2114 -> -11.176221 | G5: 0.88096802 | H5: -0.45463791 | I5: =H5*27.2114 -> -12.371334 | J5: 0.92125435 | K5: -0.44720305 | L5: =K5*27.2114 -> -12.169021 | M5: 0.91386343 | N5: 12.62 | O5: =-E5-N5 -> 1.0717479 | P5: =-F5-N5 -> -1.4437791 | Q5: =-I5-N5 -> -0.24866608 | R5: =-L5-N5 -> -0.45097903
A6: co | B6: 5sgg | C6: -0.55416253 | D6: -0.51634944 | E6: =C6*27.2114 -> -15.079538 | F6: =D6*27.2114 -> -14.050591 | G6: 0.91299065 | H6: -0.52428278 | I6: =H6*27.2114 -> -14.266468 | J6: 0.91196602 | K6: -0.52311417 | L6: =K6*27.2114 -> -14.234669 | M6: 0.91213407 | N6: 14.01 | O6: =-E6-N6 -> 1.0695383 | P6: =-F6-N6 -> 0.040591082 | Q6: =-I6-N6 -> 0.2564683 | R6: =-L6-N6 -> 0.22466906
A7: nh3 | B7: 3a1 | C7: -0.42678556 | D7: -0.37412602 | E7: =C7*27.2114 -> -11.613433 | F7: =D7*27.2114 -> -10.180493 | G7: 0.89899093 | H7: -0.39536 | I7: =H7*27.2114 -> -10.758299 | J7: 0.9186086 | K7: -0.39219087 | L7: =K7*27.2114 -> -10.672063 | M7: 0.91555251 | N7: 10.8 | O7: =-E7-N7 -> 0.81343264 | P7: =-F7-N7 -> -0.61950716 | Q7: =-I7-N7 -> -0.041700819 | R7: =-L7-N7 -> -0.12793748
A8: f2 | B8: 1pig | C8: -0.66533287 | D8: -0.52241238 | E8: =C8*27.2114 -> -18.104639 | F8: =D8*27.2114 -> -14.215572 | G8: 0.87066913 | H8: -0.5757918 | I8: =H8*27.2114 -> -15.668101 | J8: 0.89828089 | K8: -0.56636854 | L8: =K8*27.2114 -> -15.411681 | M8: 0.89318168 | N8: 15.87 | O8: =-E8-N8 -> 2.234639 | P8: =-F8-N8 -> -1.6544278 | Q8: =-I8-N8 -> -0.20189897 | R8: =-L8-N8 -> -0.45831914
A9: o3 | B9: 6a1 | C9: -0.54977 | D9: -0.41281 | E9: =C9*27.2114 -> -14.960011 | F9: =D9*27.2114 -> -11.233138 | G9: 0.815 | H9: -0.49932 | I9: =H9*27.2114 -> -13.587196 | J9: 0.899 | K9: -0.47793 | L9: =K9*27.2114 -> -13.005144 | M9: 0.87 | N9: 12.73 | O9: =-E9-N9 -> 2.2300114 | P9: =-F9-N9 -> -1.496862 | Q9: =-I9-N9 -> 0.85719625 | R9: =-L9-N9 -> 0.2751444
A10: h2co | B10: 2b2 | C10: -0.44215253 | D10: -0.36546393 | E10: =C10*27.2114 -> -12.031589 | F10: =D10*27.2114 -> -9.9447853 | G10: 0.88267262 | H10: -0.4015024 | I10: =H10*27.2114 -> -10.925442 | J10: 0.91633916 | K10: -0.39545505 | L10: =K10*27.2114 -> -10.760886 | M10: 0.91027957 | N10: 10.9 | O10: =-E10-N10 -> 1.1315894 | P10: =-F10-N10 -> -0.95521471 | Q10: =-I10-N10 -> 0.025442396 | R10: =-L10-N10 -> -0.13911445
A11: c2h2 | B11: 1piu | C11: -0.40921224 | D11: -0.41616641 | E11: =C11*27.2114 -> -11.135238 | F11: =D11*27.2114 -> -11.324471 | G11: 0.90590522 | H11: -0.42406959 | I11: =H11*27.2114 -> -11.539527 | J11: 0.91305518 | K11: -0.42305846 | L11: =K11*27.2114 -> -11.512013 | M11: 0.91212628 | N11: 11.49 | O11: =-E11-N11 -> -0.35476206 | P11: =-F11-N11 -> -0.16552943 | Q11: =-I11-N11 -> 0.049527183 | R11: =-L11-N11 -> 0.022012866
A12: c2h4 | B12: 1b3u | C12: -0.37635105 | D12: -0.37981663 | E12: =C12*27.2114 -> -10.241039 | F12: =D12*27.2114 -> -10.335342 | G12: 0.9079952 | H12: -0.38817744 | I12: =H12*27.2114 -> -10.562852 | J12: 0.91481828 | K12: -0.38704208 | L12: =K12*27.2114 -> -10.531957 | M12: 0.91387792 | N12: 10.68 | O12: =-E12-N12 -> -0.43896102 | P12: =-F12-N12 -> -0.34465788 | Q12: =-I12-N12 -> -0.11714849 | R12: =-L12-N12 -> -0.1480432
A13: hcn | B13: 1pi | C13: -0.49511339 | D13: -0.50236254 | E13: =C13*27.2114 -> -13.472728 | F13: =D13*27.2114 -> -13.669988 | G13: 0.90126076 | H13: -0.51285623 | I13: =H13*27.2114 -> -13.955536 | J13: 0.91253555 | K13: -0.51154544 | L13: =K13*27.2114 -> -13.919867 | M13: 0.91109136 | N13: 13.61 | O13: =-E13-N13 -> -0.13727151 | P13: =-F13-N13 -> 0.05998805 | Q13: =-I13-N13 -> 0.34553606 | R13: =-L13-N13 -> 0.30986747
A14: nno | B14: 2pi | C14: -0.49040041 | D14: -0.4685272 | E14: =C14*27.2114 -> -13.344482 | F14: =D14*27.2114 -> -12.749281 | G14: 0.86877404 | H14: -0.50538537 | I14: =H14*27.2114 -> -13.752243 | J14: 0.90696779 | K14: -0.49920041 | L14: =K14*27.2114 -> -13.583942 | M14: 0.90004985 | N14: 12.89 | O14: =-E14-N14 -> 0.45448179 | P14: =-F14-N14 -> -0.14071882 | Q14: =-I14-N14 -> 0.86224341 | R14: =-L14-N14 -> 0.6939421
A15: co2 | B15: 1pig | C15: -0.54276 | D15: -0.48146 | E15: =C15*27.2114 -> -14.769259 | F15: =D15*27.2114 -> -13.101201 | G15: 0.875 | H15: -0.5164 | I15: =H15*27.2114 -> -14.051967 | J15: 0.904 | K15: -0.51106 | L15: =K15*27.2114 -> -13.906658 | M15: 0.899 | N15: 13.79 | O15: =-E15-N15 -> 0.97925946 | P15: =-F15-N15 -> -0.68879936 | Q15: =-I15-N15 -> 0.26196696 | R15: =-L15-N15 -> 0.11665808
A16: hf | B16: 1pi | C16: -0.64388968 | D16: -0.53999018 | E16: =C16*27.2114 -> -17.52114 | F16: =D16*27.2114 -> -14.693889 | G16: 0.89959515 | H16: -0.58674623 | I16: =H16*27.2114 -> -15.966186 | J16: 0.93524975 | K16: -0.57976626 | L16: =K16*27.2114 -> -15.776252 | M16: 0.92955182 | N16: 16.19 | O16: =-E16-N16 -> 1.3311397 | P16: =-F16-N16 -> -1.4961111 | Q16: =-I16-N16 -> -0.22381377 | R16: =-L16-N16 -> -0.41374838
... A36: pn | B36: sg | C36: -0.48428412 | D36: -0.40454903 | E36: =C36*27.2114 -> -13.178049 | F36: =D36*27.2114 -> -11.008345 | G36: 0.8357866 | H36: -0.46298873 | I36: =H36*27.2114 -> -12.598572 | J36: 0.92113579 | K36: -0.44852513 | L36: =K36*27.2114 -> -12.204997 | M36: 0.89641591 | N36: 11.88 | O36: =-E36-N36 -> 1.298049 | P36: =-F36-N36 -> -0.87165458 | Q36: =-I36-N36 -> 0.71857158 | R36: =-L36-N36 -> 0.32499661
N38: SGN AVE | O38: =IFERROR(__xludf.DUMMYFUNCTION("ARRAYFORMULA(SUM(FILTER(O2:O36, ROW(O2:O36)<>3, ROW(O2:O36)<>4)) / (ROWS(O2:O36)-2))"),0.815058378964611) -> 0.81505838 | P38: =IFERROR(__xludf.DUMMYFUNCTION("ARRAYFORMULA(SUM(FILTER(P2:P36, ROW(P2:P36)<>3, ROW(P2:P36)<>4)) / (ROWS(P2:P36)-2))"),-0.400333474541741) -> -0.40033347 | Q38: =IFERROR(__xludf.DUMMYFUNCTION("ARRAYFORMULA(SUM(FILTER(Q2:Q36, ROW(Q2:Q36)<>3, ROW(Q2:Q36)<>4)) / (ROWS(Q2:Q36)-2))"),0.201972922884059) -> 0.20197292 | R38: =IFERROR(__xludf.DUMMYFUNCTION("ARRAYFORMULA(SUM(FILTER(R2:R36, ROW(R2:R36)<>3, ROW(R2:R36)<>4)) / (ROWS(R2:R36)-2))"),0.0936191033998893) -> 0.093619103
N39: MAE | O39: =IFERROR(__xludf.DUMMYFUNCTION("ARRAYFORMULA(SUM(ABS(FILTER(O2:O36, ROW(O2:O36)<>3, ROW(O2:O36)<>4))) / (ROWS(O2:O36)-2))"),0.970558943529657) -> 0.97055894 | P39: =IFERROR(__xludf.DUMMYFUNCTION("ARRAYFORMULA(SUM(ABS(FILTER(P2:P36, ROW(P2:P36)<>3, ROW(P2:P36)<>4))) / (ROWS(P2:P36)-2))"),0.650865105651796) -> 0.65086511 | Q39: =IFERROR(__xludf.DUMMYFUNCTION("ARRAYFORMULA(SUM(ABS(FILTER(Q2:Q36, ROW(Q2:Q36)<>3, ROW(Q2:Q36)<>4))) / (ROWS(Q2:Q36)-2))"),0.409667049122543) -> 0.40966705 | R39: =IFERROR(__xludf.DUMMYFUNCTION("ARRAYFORMULA(SUM(ABS(FILTER(R2:R36, ROW(R2:R36)<>3, ROW(R2:R36)<>4))) / (ROWS(R2:R36)-2))"),0.378980032697712) -> 0.37898003
N40: RMSD | O40: =IFERROR(__xludf.DUMMYFUNCTION("ARRAYFORMULA(sqrt(SUM(ABS(FILTER(O2:O36, ROW(O2:O36)<>3, ROW(O2:O36)<>4))^2) / (ROWS(O2:O36)-2)))"),1.14367053662466) -> 1.1436705 | P40: =IFERROR(__xludf.DUMMYFUNCTION("ARRAYFORMULA(sqrt(SUM(ABS(FILTER(P2:P36, ROW(P2:P36)<>3, ROW(P2:P36)<>4))^2) / (ROWS(P2:P36)-2)))"),0.857000974767338) -> 0.85700097 | Q40: =IFERROR(__xludf.DUMMYFUNCTION("ARRAYFORMULA(sqrt(SUM(ABS(FILTER(Q2:Q36, ROW(Q2:Q36)<>3, ROW(Q2:Q36)<>4))^2) / (ROWS(Q2:Q36)-2)))"),0.512607199865353) -> 0.5126072 | R40: =IFERROR(__xludf.DUMMYFUNCTION("ARRAYFORMULA(sqrt(SUM(ABS(FILTER(R2:R36, ROW(R2:R36)<>3, ROW(R2:R36)<>4))^2) / (ROWS(R2:R36)-2)))"),0.473777650238518) -> 0.47377765
O41: semi KT | P41: semi D2 | Q41: semi P3 | R41: semi P3+
O43: AVE PS | P43: =IFERROR(__xludf.DUMMYFUNCTION("AVERAGE(FILTER(G2:G36, (ROW(G2:G36)<>3) * (ROW(G2:G36)<>4)))"),0.899720901345894) -> 0.8997209 | Q43: =IFERROR(__xludf.DUMMYFUNCTION("AVERAGE(FILTER(J2:J36, (ROW(J2:J36)<>3) * (ROW(J2:J36)<>4)))"),0.918883185701217) -> 0.91888319 | R43: =IFERROR(__xludf.DUMMYFUNCTION("AVERAGE(FILTER(M2:M36, (ROW(M2:M36)<>3) * (ROW(M2:M36)<>4)))"),0.9137785999868) -> 0.9137786

Sheet SFigure7-Data-2
A1: HF | B1: orb | C1: kt | D1: d2 | E1: kt | F1: d2 | G1: ps | H1: p3 | I1: p3 | J1: ps | K1: p3+ | L1: p3+ | M1: ps | N1: bd-t1 | O1: sgn err kt | P1: sgn err d2 | Q1: sgn err p3 | R1: sgn err p3+
A2: n2 | B2: 3sgg | C2: -0.63291374 | D2: -0.55366482 | E2: =C2*27.2114 -> -17.222469 | F2: =D2*27.2114 -> -15.065995 | G2: 0.88387124 | H2: -0.58635967 | I2: =H2*27.2114 -> -15.955667 | J2: 0.90743298 | K2: -0.58027696 | L2: =K2*27.2114 -> -15.790148 | M2: 0.90284026 | N2: 15.327 | O2: =-E2-N2 -> 1.8954688 | P2: =-F2-N2 -> -0.26100522 | Q2: =-I2-N2 -> 0.62866747 | R2: =-L2-N2 -> 0.46314842
